ERROR:tornado.application:Exception in callback functools.partial(<function wrap.<locals>.null_wrapper at 0x7fb0c826b620>)
concurrent.futures.process._RemoteTraceback: 
"""
Traceback (most recent call last):
  File "/usr/lib/python3.5/concurrent/futures/process.py", line 175, in _process_worker
    r = call_item.fn(*call_item.args, **call_item.kwargs)
  File "/usr/lib/python3.5/concurrent/futures/process.py", line 153, in _process_chunk
    return [fn(*args) for args in chunk]
  File "/usr/lib/python3.5/concurrent/futures/process.py", line 153, in <listcomp>
    return [fn(*args) for args in chunk]
  File "Preprocessror.py", line 33, in preprocesse_file
    with open(name) as fobj:
FileNotFoundError: [Errno 2] No such file or directory: './validate/sscgsoecc1'
"""

The above exception was the direct cause of the following exception:

Traceback (most recent call last):
  File "/home/ivan/diplom/cognitive_mapper/api/data_mining_app/diplom/env/lib/python3.5/site-packages/tornado/ioloop.py", line 604, in _run_callback
    ret = callback()
  File "/home/ivan/diplom/cognitive_mapper/api/data_mining_app/diplom/env/lib/python3.5/site-packages/tornado/stack_context.py", line 275, in null_wrapper
    return fn(*args, **kwargs)
  File "Preprocessror.py", line 58, in loop
    result = list(self.workers.do([task], self.method))[0]
  File "/usr/lib/python3.5/concurrent/futures/_base.py", line 556, in result_iterator
    yield future.result()
  File "/usr/lib/python3.5/concurrent/futures/_base.py", line 405, in result
    return self.__get_result()
  File "/usr/lib/python3.5/concurrent/futures/_base.py", line 357, in __get_result
    raise self._exception
FileNotFoundError: [Errno 2] No such file or directory: './validate/sscgsoecc1'
